Workbook

Sheet Read Me
A1: Master Item Bank
A2: One source of truth for every practice item, assessment item, explanation, and standard link.
A3: What this is | B3: A single bank of items. Lessons and assessment packages are VIEWS pulled from this bank by filtering, rather than hand-built each time. Author an item once, reuse it in a lesson, a summative form, a delayed retake, a capstone, or a spiral review in a later unit.
A4: How to use it | B4: Work on the Items tab. Filter by Standard code, Item type, or Form / Use to pull the set you need. Controlled columns have dropdowns (see the Enums tab) so values stay consistent. The Standards tab holds the verbatim standard each item links to. The Coverage tab counts items per standard so gaps are visible.
A5: Why it is domain-agnostic | B5: The schema carries the scoring model, not a quiz assumption. A math item is type MC, scored auto-key by the system. An avionics item is type Performance, scored by observed sign-off from a qualified evaluator, with References pointing to the maintenance manual or AC 43.13. A history item is type Constructed, scored by rubric. Same table, any domain.
A6: Item types | B6: MC (selected response), Constructed (written explanation), Performance (observed or produced task). Use Performance for procedural and hands-on standards.
A7: Scoring method | B7: auto-key (the system grades it), rubric (an adult grades against criteria), observed sign-off (a qualified evaluator watches and signs). Who scores names the role.
A8: Form / Use | B8: Where the item is used: Lesson practice, Lesson mastery, Summative A, Delayed B, Capstone, Performance task, Decode game. One item can be promoted from practice to a form by changing this field.
A9: Non-compensatory note | B9: Performance and Constructed items carry the weight a credential rests on. A critical defect on those is an automatic not-yet regardless of MC score. The Misconception targeted column records the defect each item is built to catch.
A10: What is seeded now | B10: All of Grade 2 Unit 1: the A.2 through A.5 assessment items (Forms A and B plus the constructed items), the four performance tasks, a full A.1 set, and the unit capstone. 95 items across the five Unit 1 standards.
A11: Next steps | B11: Bulk-import the remaining Grade 2, 3, and 8 standards into the Standards tab, then author or import their items. Long term, export this bank to JSON so the lesson files read their questions from the bank instead of hardcoding them.
A12: Last updated | B12: 2026-05-22

Sheet Standards
A1: Standard code | B1: Grade | C1: Domain | D1: Standard text (verbatim) | E1: Common Core alignment | F1: Source | G1: Unit | H1: Recipe type
A2: 2.NBT.A.1 | B2: 2 | C2: NBT | D2: Understand three-digit numbers are composed of hundreds, tens and ones. | E2: 2.NBT.A.1 | F2: Missouri Learning Standards (DESE 2016) | G2: Unit 1: Place Value to 1,000 | H2: Conceptual
A3: 2.NBT.A.2 | B3: 2 | C3: NBT | D3: Understand that 100 can be thought of as 10 tens, called a "hundred". | E3: 2.NBT.A.1.a | F3: Missouri Learning Standards (DESE 2016) | G3: Unit 1: Place Value to 1,000 | H3: Conceptual
A4: 2.NBT.A.3 | B4: 2 | C4: NBT | D4: Count within 1000 by 1s, 10s and 100s starting with any number. | E4: 2.NBT.A.2 | F4: Missouri Learning Standards (DESE 2016) | G4: Unit 1: Place Value to 1,000 | H4: Procedural
A5: 2.NBT.A.4 | B5: 2 | C5: NBT | D5: Read and write numbers to 1000 using number names, base-ten numerals and expanded form. | E5: 2.NBT.A.3 | F5: Missouri Learning Standards (DESE 2016) | G5: Unit 1: Place Value to 1,000 | H5: Conceptual
A6: 2.NBT.A.5 | B6: 2 | C6: NBT | D6: Compare two three-digit numbers using the symbols >, = or <. | E6: 2.NBT.A.4 | F6: Missouri Learning Standards (DESE 2016) | G6: Unit 1: Place Value to 1,000 | H6: Conceptual

Sheet Items
A1: Item ID | B1: Standard code | C1: Grade | D1: Domain | E1: Unit | F1: Lesson / Atom | G1: Recipe type | H1: Item type | I1: Cognitive level | J1: Form / Use | K1: Stem | L1: Option A | M1: Option B | N1: Option C | O1: Option D | P1: Key | Q1: Explanation | R1: Misconception targeted | S1: Points | T1: Scoring method | U1: Who scores | V1: References | W1: Status | X1: Last updated
A2: 2.NBT.A.2-A1 | B2: 2.NBT.A.2 | C2: 2 | D2: NBT | E2: Unit 1: Place Value to 1,000 | F2: G2-U1 / 2.NBT.A.2 | G2: Conceptual | H2: MC | I2: Remember | J2: Summative A | K2: How many tens make one hundred? | L2: 10 | M2: 5 | N2: 100 | O2: 1000 | P2: ten | Q2: Counting by tens, it takes ten tens to reach one hundred. | R2: 100 = face value of the number; 5 = half error; 1000 = over-bundling (ten hundreds). | S2: 1 | T2: auto-key | U2: system | V2: Missouri Learning Standards (DESE 2016); Common Core 2.NBT.A; base-ten manipulatives | W2: Ready | X2: 2026-05-22
A3: 2.NBT.A.2-A2 | B3: 2.NBT.A.2 | C3: 2 | D3: NBT | E3: Unit 1: Place Value to 1,000 | F3: G2-U1 / 2.NBT.A.2 | G3: Conceptual | H3: MC | I3: Understand | J3: Summative A | K3: 100 is the same as how many tens? | L3: 1 | M3: 100 | N3: 10 | O3: 1000 | P3: 10 | Q3: One hundred is exactly ten tens. | R3: 1 = a hundred is one unit only; 100 = face-value error; 1000 = over-bundling. | S3: 1 | T3: auto-key | U3: system | V3: Missouri Learning Standards (DESE 2016); Common Core 2.NBT.A; base-ten manipulatives | W3: Ready | X3: 2026-05-22
A4: 2.NBT.A.2-A3 | B4: 2.NBT.A.2 | C4: 2 | D4: NBT | E4: Unit 1: Place Value to 1,000 | F4: G2-U1 / 2.NBT.A.2 | G4: Conceptual | H4: MC | I4: Understand | J4: Summative A | K4: Ten tens is the same as how many ones? | L4: 100 | M4: 10 | N4: 20 | O4: 1000 | P4: 100 | Q4: Ten tens equals one hundred, which is 100 ones. | R4: 10 = counting the tens not the ones; 20 = doubling; 1000 = over-bundling. | S4: 1 | T4: auto-key | U4: system | V4: Missouri Learning Standards (DESE 2016); Common Core 2.NBT.A; base-ten manipulatives | W4: Ready | X4: 2026-05-22
A5: 2.NBT.A.2-A4 | B5: 2.NBT.A.2 | C5: 2 | D5: NBT | E5: Unit 1: Place Value to 1,000 | F5: G2-U1 / 2.NBT.A.2 | G5: Conceptual | H5: MC | I5: Understand | J5: Summative A | K5: Which group shows one hundred? | L5: 10 ones | M5: 1 ten | N5: 10 tens | O5: 100 tens | P5: 10 tens | Q5: One hundred is ten tens bundled together. | R5: 10 ones = the ten-ones error; 1 ten = just a ten; 100 tens = over-counting. | S5: 1 | T5: auto-key | U5: system | V5: Missouri Learning Standards (DESE 2016); Common Core 2.NBT.A; base-ten manipulatives | W5: Ready | X5: 2026-05-22
A6: 2.NBT.A.2-A5 | B6: 2.NBT.A.2 | C6: 2 | D6: NBT | E6: Unit 1: Place Value to 1,000 | F6: G2-U1 / 2.NBT.A.2 | G6: Conceptual | H6: MC | I6: Understand | J6: Summative A | K6: You bundle ten tens together. What single unit do you have now? | L6: one ten | M6: one hundred | N6: one thousand | O6: ten ones | P6: one hundred | Q6: Ten tens snap together into one new unit, one hundred. | R6: one ten = no bundling happened; one thousand = over-bundling; ten ones = unit confusion. | S6: 1 | T6: auto-key | U6: system | V6: Missouri Learning Standards (DESE 2016); Common Core 2.NBT.A; base-ten manipulatives | W6: Ready | X6: 2026-05-22
A7: 2.NBT.A.2-A6 | B7: 2.NBT.A.2 | C7: 2 | D7: NBT | E7: Unit 1: Place Value to 1,000 | F7: G2-U1 / 2.NBT.A.2 | G7: Conceptual | H7: MC | I7: Apply | J7: Summative A | K7: One hundred can be broken apart into how many tens? | L7: 100 | M7: 5 | N7: 1 | O7: 10 | P7: 10 | Q7: One hundred unbundles back into ten tens. | R7: 100 = breaking into ones not tens; 5 = half; 1 = treating a hundred as one ten. | S7: 1 | T7: auto-key | U7: system | V7: Missouri Learning Standards (DESE 2016); Common Core 2.NBT.A; base-ten manipulatives | W7: Ready | X7: 2026-05-22
A8: 2.NBT.A.2-A7 | B8: 2.NBT.A.2 | C8: 2 | D8: NBT | E8: Unit 1: Place Value to 1,000 | F8: G2-U1 / 2.NBT.A.2 | G8: Conceptual | H8: MC | I8: Apply | J8: Summative A | K8: How many tens in all are in 2 hundreds (200)? | L8: 2 | M8: 200 | N8: 20 | O8: 10 | P8: 20 | Q8: Each hundred is ten tens, so two hundreds is 20 tens. | R8: 2 = hundreds digit only; 200 = ones; 10 = tens in one hundred, forgot to double. | S8: 1 | T8: auto-key | U8: system | V8: Missouri Learning Standards (DESE 2016); Common Core 2.NBT.A; base-ten manipulatives | W8: Ready | X8: 2026-05-22
A9: 2.NBT.A.2-A8 | B9: 2.NBT.A.2 | C9: 2 | D9: NBT | E9: Unit 1: Place Value to 1,000 | F9: G2-U1 / 2.NBT.A.2 | G9: Conceptual | H9: MC | I9: Apply | J9: Summative A | K9: A store has 10 boxes of markers. Each box holds 10 markers. How many markers in all, and what is that group called? | L9: 100 markers, one hundred | M9: 10 markers, one ten | N9: 20 markers, two tens | O9: 1000 markers, one thousand | P9: 100 markers, one hundred | Q9: Ten groups of ten is ten tens, which is one hundred, or 100 markers. | R9: one ten = grouped by ones; two tens = added the groups; one thousand = over-bundling. | S9: 1 | T9: auto-key | U9: system | V9: Missouri Learning Standards (DESE 2016); Common Core 2.NBT.A; base-ten manipulatives | W9: Ready | X9: 2026-05-22
A10: 2.NBT.A.2-A9 | B10: 2.NBT.A.2 | C10: 2 | D10: NBT | E10: Unit 1: Place Value to 1,000 | F10: G2-U1 / 2.NBT.A.2 | G10: Conceptual | H10: Constructed | I10: Analyze | J10: Summative A | K10: Mia says one hundred is the same as ten ones. Explain why Mia is wrong, and tell what ten ones really make. | P10: Must state that ten ones make only one ten (not a hundred), and that one hundred is ten tens, which is 100 ones. | Q10: Scored by rubric. Targets the ten-ones misconception directly. | S10: 2 | T10: rubric | U10: adult | V10: Missouri Learning Standards (DESE 2016); Common Core 2.NBT.A; base-ten manipulatives | W10: Ready | X10: 2026-05-22
A11: 2.NBT.A.2-B1 | B11: 2.NBT.A.2 | C11: 2 | D11: NBT | E11: Unit 1: Place Value to 1,000 | F11: G2-U1 / 2.NBT.A.2 | G11: Conceptual | H11: MC | I11: Remember | J11: Delayed B | K11: Count by tens to one hundred. How many tens did you count? | L11: 10 | M11: 9 | N11: 100 | O11: 5 | P11: 10 | Q11: Ten tens reach one hundred. | R11: Parallel to A1. | S11: 1 | T11: auto-key | U11: system | V11: Missouri Learning Standards (DESE 2016); Common Core 2.NBT.A; base-ten manipulatives | W11: Ready | X11: 2026-05-22
A12: 2.NBT.A.2-B2 | B12: 2.NBT.A.2 | C12: 2 | D12: NBT | E12: Unit 1: Place Value to 1,000 | F12: G2-U1 / 2.NBT.A.2 | G12: Conceptual | H12: MC | I12: Understand | J12: Delayed B | K12: One hundred is the same as how many tens? | L12: 100 | M12: 10 | N12: 1 | O12: 1000 | P12: 10 | Q12: One hundred is ten tens. | R12: Parallel to A2. | S12: 1 | T12: auto-key | U12: system | V12: Missouri Learning Standards (DESE 2016); Common Core 2.NBT.A; base-ten manipulatives | W12: Ready | X12: 2026-05-22
A13: 2.NBT.A.2-B3 | B13: 2.NBT.A.2 | C13: 2 | D13: NBT | E13: Unit 1: Place Value to 1,000 | F13: G2-U1 / 2.NBT.A.2 | G13: Conceptual | H13: MC | I13: Understand | J13: Delayed B | K13: How many ones are in ten tens? | L13: 10 | M13: 1000 | N13: 100 | O13: 110 | P13: 100 | Q13: Ten tens is one hundred, which is 100 ones. | R13: Parallel to A3. | S13: 1 | T13: auto-key | U13: system | V13: Missouri Learning Standards (DESE 2016); Common Core 2.NBT.A; base-ten manipulatives | W13: Ready | X13: 2026-05-22
A14: 2.NBT.A.2-B4 | B14: 2.NBT.A.2 | C14: 2 | D14: NBT | E14: Unit 1: Place Value to 1,000 | F14: G2-U1 / 2.NBT.A.2 | G14: Conceptual | H14: MC | I14: Understand | J14: Delayed B | K14: Which group shows one hundred? | L14: 10 tens | M14: 10 ones | N14: 1 ten | O14: 2 tens | P14: 10 tens | Q14: One hundred is ten tens. | R14: Parallel to A4. | S14: 1 | T14: auto-key | U14: system | V14: Missouri Learning Standards (DESE 2016); Common Core 2.NBT.A; base-ten manipulatives | W14: Ready | X14: 2026-05-22
A15: 2.NBT.A.2-B5 | B15: 2.NBT.A.2 | C15: 2 | D15: NBT | E15: Unit 1: Place Value to 1,000 | F15: G2-U1 / 2.NBT.A.2 | G15: Conceptual | H15: MC | I15: Understand | J15: Delayed B | K15: You snap ten ten-rods together. What single unit is that? | L15: ten ones | M15: one thousand | N15: one hundred | O15: one ten | P15: one hundred | Q15: Ten tens make one hundred. | R15: Parallel to A5. | S15: 1 | T15: auto-key | U15: system | V15: Missouri Learning Standards (DESE 2016); Common Core 2.NBT.A; base-ten manipulatives | W15: Ready | X15: 2026-05-22
A16: 2.NBT.A.2-B6 | B16: 2.NBT.A.2 | C16: 2 | D16: NBT | E16: Unit 1: Place Value to 1,000 | F16: G2-U1 / 2.NBT.A.2 | G16: Conceptual | H16: MC | I16: Apply | J16: Delayed B | K16: One hundred unbundles into how many tens? | L16: 10 | M16: 1 | N16: 100 | O16: 20 | P16: 10 | Q16: One hundred is ten tens. | R16: Parallel to A6. | S16: 1 | T16: auto-key | U16: system | V16: Missouri Learning Standards (DESE 2016); Common Core 2.NBT.A; base-ten manipulatives | W16: Ready | X16: 2026-05-22
A17: 2.NBT.A.2-B7 | B17: 2.NBT.A.2 | C17: 2 | D17: NBT | E17: Unit 1: Place Value to 1,000 | F17: G2-U1 / 2.NBT.A.2 | G17: Conceptual | H17: MC | I17: Apply | J17: Delayed B | K17: How many tens in all are in 3 hundreds (300)? | L17: 3 | M17: 30 | N17: 300 | O17: 10 | P17: 30 | Q17: Each hundred is ten tens, so three hundreds is 30 tens. | R17: Parallel to A7. | S17: 1 | T17: auto-key | U17: system | V17: Missouri Learning Standards (DESE 2016); Common Core 2.NBT.A; base-ten manipulatives | W17: Ready | X17: 2026-05-22
A18: 2.NBT.A.2-B8 | B18: 2.NBT.A.2 | C18: 2 | D18: NBT | E18: Unit 1: Place Value to 1,000 | F18: G2-U1 / 2.NBT.A.2 | G18: Conceptual | H18: MC | I18: Apply | J18: Delayed B | K18: A teacher has 10 bags of stickers. Each bag holds 10 stickers. How many stickers in all, and what is that group called? | L18: 10 stickers, one ten | M18: 100 stickers, one hundred | N18: 1000 stickers, one thousand | O18: 20 stickers, two tens | P18: 100 stickers, one hundred | Q18: Ten groups of ten is ten tens, one hundred, or 100 stickers. | R18: Parallel to A8. | S18: 1 | T18: auto-key | U18: system | V18: Missouri Learning Standards (DESE 2016); Common Core 2.NBT.A; base-ten manipulatives | W18: Ready | X18: 2026-05-22
A19: 2.NBT.A.2-B9 | B19: 2.NBT.A.2 | C19: 2 | D19: NBT | E19: Unit 1: Place Value to 1,000 | F19: G2-U1 / 2.NBT.A.2 | G19: Conceptual | H19: Constructed | I19: Analyze | J19: Delayed B | K19: Leo says ten tens make one ten. Explain why Leo is wrong, and tell what ten tens really make. | P19: Must state that ten tens make one hundred (100 ones), not one ten, because bundling ten tens creates the next larger unit. | Q19: Parallel to A9. | S19: 2 | T19: rubric | U19: adult | V19: Missouri Learning Standards (DESE 2016); Common Core 2.NBT.A; base-ten manipulatives | W19: Ready | X19: 2026-05-22
A20: 2.NBT.A.3-A1 | B20: 2.NBT.A.3 | C20: 2 | D20: NBT | E20: Unit 1: Place Value to 1,000 | F20: G2-U1 / 2.NBT.A.3 | G20: Procedural | H20: MC | I20: Remember | J20: Summative A | K20: Count by tens: 340, 350, 360 ... what comes next? | L20: 370 | M20: 361 | N20: 460 | O20: 350 | P20: 370 | Q20: Counting on by ten increases the tens digit by one. | R20: 361 = added 1 not 10; 460 = added 100; 350 = repeated the last number. | S20: 1 | T20: auto-key | U20: system | V20: Missouri Learning Standards (DESE 2016); Common Core 2.NBT.A; base-ten manipulatives | W20: Ready | X20: 2026-05-22
A21: 2.NBT.A.3-A2 | B21: 2.NBT.A.3 | C21: 2 | D21: NBT | E21: Unit 1: Place Value to 1,000 | F21: G2-U1 / 2.NBT.A.3 | G21: Procedural | H21: MC | I21: Understand | J21: Summative A | K21: When you count on by ten, which digit changes? | L21: the ones | M21: the tens | N21: the hundreds | O21: none of them | P21: the tens | Q21: Adding ten changes the tens place. | R21: ones = treating +10 like +1; hundreds = confusing with +100; none = thinks the number is unchanged. | S21: 1 | T21: auto-key | U21: system | V21: Missouri Learning Standards (DESE 2016); Common Core 2.NBT.A; base-ten manipulatives | W21: Ready | X21: 2026-05-22
A22: 2.NBT.A.3-A3 | B22: 2.NBT.A.3 | C22: 2 | D22: NBT | E22: Unit 1: Place Value to 1,000 | F22: G2-U1 / 2.NBT.A.3 | G22: Procedural | H22: MC | I22: Understand | J22: Summative A | K22: Start at 23 and count by tens: 23, 33 ... what comes next? | L22: 24 | M22: 123 | N22: 43 | O22: 33 | P22: 43 | Q22: You may start a skip count at any number; by tens, 33 then 43. | R22: 24 = counted by 1; 123 = counted by 100; 33 = repeated. | S22: 1 | T22: auto-key | U22: system | V22: Missouri Learning Standards (DESE 2016); Common Core 2.NBT.A; base-ten manipulatives | W22: Ready | X22: 2026-05-22
A23: 2.NBT.A.3-A4 | B23: 2.NBT.A.3 | C23: 2 | D23: NBT | E23: Unit 1: Place Value to 1,000 | F23: G2-U1 / 2.NBT.A.3 | G23: Procedural | H23: MC | I23: Apply | J23: Summative A | K23: Count on by ten from 295: 295 ... what comes next? | L23: 296 | M23: 395 | N23: 285 | O23: 305 | P23: 305 | Q23: Nine tens plus one ten makes ten tens, which rolls into a new hundred: 305. | R23: 296 = added 1; 395 = added 100; 285 = subtracted 10. | S23: 1 | T23: auto-key | U23: system | V23: Missouri Learning Standards (DESE 2016); Common Core 2.NBT.A; base-ten manipulatives | W23: Ready | X23: 2026-05-22
A24: 2.NBT.A.3-A5 | B24: 2.NBT.A.3 | C24: 2 | D24: NBT | E24: Unit 1: Place Value to 1,000 | F24: G2-U1 / 2.NBT.A.3 | G24: Procedural | H24: MC | I24: Apply | J24: Summative A | K24: Count on by 1: 199 ... what comes next? | L24: 200 | M24: 1910 | N24: 190 | O24: 100 | P24: 200 | Q24: 199 plus 1 rolls the ones and tens over into 200. | R24: 1910 = wrote the digits side by side; 190 = went backward; 100 = unrelated. | S24: 1 | T24: auto-key | U24: system | V24: Missouri Learning Standards (DESE 2016); Common Core 2.NBT.A; base-ten manipulatives | W24: Ready | X24: 2026-05-22
A25: 2.NBT.A.3-A6 | B25: 2.NBT.A.3 | C25: 2 | D25: NBT | E25: Unit 1: Place Value to 1,000 | F25: G2-U1 / 2.NBT.A.3 | G25: Procedural | H25: MC | I25: Apply | J25: Summative A | K25: Count by hundreds: 408, 508, 608 ... what comes next? | L25: 618 | M25: 708 | N25: 4080 | O25: 508 | P25: 708 | Q25: Counting on by one hundred increases the hundreds digit by one. | R25: 618 = added 110; 4080 = wrote digits side by side; 508 = repeated. | S25: 1 | T25: auto-key | U25: system | V25: Missouri Learning Standards (DESE 2016); Common Core 2.NBT.A; base-ten manipulatives | W25: Ready | X25: 2026-05-22
A26: 2.NBT.A.3-A7 | B26: 2.NBT.A.3 | C26: 2 | D26: NBT | E26: Unit 1: Place Value to 1,000 | F26: G2-U1 / 2.NBT.A.3 | G26: Procedural | H26: MC | I26: Apply | J26: Summative A | K26: Count back by ten: 530, 520, 510 ... what comes next? | L26: 509 | M26: 410 | N26: 500 | O26: 511 | P26: 500 | Q26: Counting back by ten lowers the tens digit by one. | R26: 509 = went back by 1; 410 = back by 100; 511 = went up by 1. | S26: 1 | T26: auto-key | U26: system | V26: Missouri Learning Standards (DESE 2016); Common Core 2.NBT.A; base-ten manipulatives | W26: Ready | X26: 2026-05-22
A27: 2.NBT.A.3-A8 | B27: 2.NBT.A.3 | C27: 2 | D27: NBT | E27: Unit 1: Place Value to 1,000 | F27: G2-U1 / 2.NBT.A.3 | G27: Procedural | H27: MC | I27: Apply | J27: Summative A | K27: Count by hundreds: 690, 790, 890 ... what comes next? | L27: 900 | M27: 891 | N27: 6900 | O27: 990 | P27: 990 | Q27: Each jump adds one hundred, so after 890 comes 990, still under 1000. | R27: 900 = added 10; 891 = added 1; 6900 = wrote digits side by side. | S27: 1 | T27: auto-key | U27: system | V27: Missouri Learning Standards (DESE 2016); Common Core 2.NBT.A; base-ten manipulatives | W27: Ready | X27: 2026-05-22
A28: 2.NBT.A.3-A9 | B28: 2.NBT.A.3 | C28: 2 | D28: NBT | E28: Unit 1: Place Value to 1,000 | F28: G2-U1 / 2.NBT.A.3 | G28: Procedural | H28: Constructed | I28: Analyze | J28: Summative A | K28: Sam counts by tens from 295 and says the next number is 296. Explain why Sam is wrong and give the correct next number. | P28: Must state that counting on by ten changes the tens (not the ones), and that 295 plus 10 crosses into a new hundred, so the correct next number is 305. | Q28: Scored by rubric. Targets the +10-acts-like-+1 error and the boundary-crossing error. | S28: 2 | T28: rubric | U28: adult | V28: Missouri Learning Standards (DESE 2016); Common Core 2.NBT.A; base-ten manipulatives | W28: Ready | X28: 2026-05-22
A29: 2.NBT.A.3-B1 | B29: 2.NBT.A.3 | C29: 2 | D29: NBT | E29: Unit 1: Place Value to 1,000 | F29: G2-U1 / 2.NBT.A.3 | G29: Procedural | H29: MC | I29: Remember | J29: Delayed B | K29: Count by tens: 510, 520, 530 ... what comes next? | L29: 540 | M29: 531 | N29: 640 | O29: 520 | P29: 540 | Q29: Counting on by ten increases the tens digit by one. | R29: Parallel to A1. | S29: 1 | T29: auto-key | U29: system | V29: Missouri Learning Standards (DESE 2016); Common Core 2.NBT.A; base-ten manipulatives | W29: Ready | X29: 2026-05-22
A30: 2.NBT.A.3-B2 | B30: 2.NBT.A.3 | C30: 2 | D30: NBT | E30: Unit 1: Place Value to 1,000 | F30: G2-U1 / 2.NBT.A.3 | G30: Procedural | H30: MC | I30: Understand | J30: Delayed B | K30: When you count on by one hundred, which digit changes? | L30: the ones | M30: the hundreds | N30: the tens | O30: none of them | P30: the hundreds | Q30: Adding one hundred changes the hundreds place. | R30: Parallel to A2. | S30: 1 | T30: auto-key | U30: system | V30: Missouri Learning Standards (DESE 2016); Common Core 2.NBT.A; base-ten manipulatives | W30: Ready | X30: 2026-05-22
A31: 2.NBT.A.3-B3 | B31: 2.NBT.A.3 | C31: 2 | D31: NBT | E31: Unit 1: Place Value to 1,000 | F31: G2-U1 / 2.NBT.A.3 | G31: Procedural | H31: MC | I31: Understand | J31: Delayed B | K31: Start at 47 and count by tens: 47, 57 ... what comes next? | L31: 48 | M31: 147 | N31: 67 | O31: 57 | P31: 67 | Q31: You may start a skip count at any number; by tens, 57 then 67. | R31: Parallel to A3. | S31: 1 | T31: auto-key | U31: system | V31: Missouri Learning Standards (DESE 2016); Common Core 2.NBT.A; base-ten manipulatives | W31: Ready | X31: 2026-05-22
A32: 2.NBT.A.3-B4 | B32: 2.NBT.A.3 | C32: 2 | D32: NBT | E32: Unit 1: Place Value to 1,000 | F32: G2-U1 / 2.NBT.A.3 | G32: Procedural | H32: MC | I32: Apply | J32: Delayed B | K32: Count on by ten from 392: 392 ... what comes next? | L32: 393 | M32: 492 | N32: 302 | O32: 402 | P32: 402 | Q32: Nine tens plus one ten rolls into a new hundred: 402. | R32: Parallel to A4. | S32: 1 | T32: auto-key | U32: system | V32: Missouri Learning Standards (DESE 2016); Common Core 2.NBT.A; base-ten manipulatives | W32: Ready | X32: 2026-05-22
A33: 2.NBT.A.3-B5 | B33: 2.NBT.A.3 | C33: 2 | D33: NBT | E33: Unit 1: Place Value to 1,000 | F33: G2-U1 / 2.NBT.A.3 | G33: Procedural | H33: MC | I33: Apply | J33: Delayed B | K33: Count on by 1: 499 ... what comes next? | L33: 500 | M33: 4910 | N33: 490 | O33: 400 | P33: 500 | Q33: 499 plus 1 rolls over into 500. | R33: Parallel to A5. | S33: 1 | T33: auto-key | U33: system | V33: Missouri Learning Standards (DESE 2016); Common Core 2.NBT.A; base-ten manipulatives | W33: Ready | X33: 2026-05-22
A34: 2.NBT.A.3-B6 | B34: 2.NBT.A.3 | C34: 2 | D34: NBT | E34: Unit 1: Place Value to 1,000 | F34: G2-U1 / 2.NBT.A.3 | G34: Procedural | H34: MC | I34: Apply | J34: Delayed B | K34: Count by hundreds: 263, 363, 463 ... what comes next? | L34: 473 | M34: 563 | N34: 2630 | O34: 363 | P34: 563 | Q34: Counting on by one hundred increases the hundreds digit by one. | R34: Parallel to A6. | S34: 1 | T34: auto-key | U34: system | V34: Missouri Learning Standards (DESE 2016); Common Core 2.NBT.A; base-ten manipulatives | W34: Ready | X34: 2026-05-22
A35: 2.NBT.A.3-B7 | B35: 2.NBT.A.3 | C35: 2 | D35: NBT | E35: Unit 1: Place Value to 1,000 | F35: G2-U1 / 2.NBT.A.3 | G35: Procedural | H35: MC | I35: Apply | J35: Delayed B | K35: Count back by one hundred: 700, 600 ... what comes next? | L35: 690 | M35: 590 | N35: 500 | O35: 501 | P35: 500 | Q35: Counting back by one hundred lowers the hundreds digit by one. | R35: Parallel to A7. | S35: 1 | T35: auto-key | U35: system | V35: Missouri Learning Standards (DESE 2016); Common Core 2.NBT.A; base-ten manipulatives | W35: Ready | X35: 2026-05-22
A36: 2.NBT.A.3-B8 | B36: 2.NBT.A.3 | C36: 2 | D36: NBT | E36: Unit 1: Place Value to 1,000 | F36: G2-U1 / 2.NBT.A.3 | G36: Procedural | H36: MC | I36: Apply | J36: Delayed B | K36: Count by hundreds: 680, 780, 880 ... what comes next? | L36: 890 | M36: 881 | N36: 6800 | O36: 980 | P36: 980 | Q36: Each jump adds one hundred, so after 880 comes 980, still under 1000. | R36: Parallel to A8. | S36: 1 | T36: auto-key | U36: system | V36: Missouri Learning Standards (DESE 2016); Common Core 2.NBT.A; base-ten manipulatives | W36: Ready | X36: 2026-05-22
A37: 2.NBT.A.3-B9 | B37: 2.NBT.A.3 | C37: 2 | D37: NBT | E37: Unit 1: Place Value to 1,000 | F37: G2-U1 / 2.NBT.A.3 | G37: Procedural | H37: Constructed | I37: Analyze | J37: Delayed B | K37: Mara counts by hundreds from 408 and says the next number is 418. Explain why Mara is wrong and give the correct next number. | P37: Must state that counting on by one hundred changes the hundreds (not the tens), so the correct next number is 508. | Q37: Parallel to A9. | S37: 2 | T37: rubric | U37: adult | V37: Missouri Learning Standards (DESE 2016); Common Core 2.NBT.A; base-ten manipulatives | W37: Ready | X37: 2026-05-22
A38: 2.NBT.A.4-A1 | B38: 2.NBT.A.4 | C38: 2 | D38: NBT | E38: Unit 1: Place Value to 1,000 | F38: G2-U1 / 2.NBT.A.4 | G38: Conceptual | H38: MC | I38: Understand | J38: Summative A | K38: Which words name the number 245? | L38: two hundred forty-five | M38: two hundred fifty-four | N38: two hundred forty | O38: twenty-four five | P38: two hundred forty-five | Q38: 245 is read as two hundred forty-five. | R38: fifty-four = swapped tens and ones; forty = dropped the ones; twenty-four five = read digits separately. | S38: 1 | T38: auto-key | U38: system | V38: Missouri Learning Standards (DESE 2016); Common Core 2.NBT.A; base-ten manipulatives | W38: Ready | X38: 2026-05-22
A39: 2.NBT.A.4-A2 | B39: 2.NBT.A.4 | C39: 2 | D39: NBT | E39: Unit 1: Place Value to 1,000 | F39: G2-U1 / 2.NBT.A.4 | G39: Conceptual | H39: MC | I39: Understand | J39: Summative A | K39: Write "three hundred sixty-one" as a number. | L39: 30061 | M39: 361 | N39: 316 | O39: 3061 | P39: 361 | Q39: Three hundreds, six tens, one one is 361. | R39: 30061 = wrote pieces side by side; 316 = swapped tens and ones; 3061 = extra zero. | S39: 1 | T39: auto-key | U39: system | V39: Missouri Learning Standards (DESE 2016); Common Core 2.NBT.A; base-ten manipulatives | W39: Ready | X39: 2026-05-22
A40: 2.NBT.A.4-A3 | B40: 2.NBT.A.4 | C40: 2 | D40: NBT | E40: Unit 1: Place Value to 1,000 | F40: G2-U1 / 2.NBT.A.4 | G40: Conceptual | H40: MC | I40: Apply | J40: Summative A | K40: Write "seven hundred four" as a number. | L40: 74 | M40: 7004 | N40: 704 | O40: 740 | P40: 704 | Q40: No tens, so a 0 holds the tens place: 704. | R40: 74 = dropped the hundreds zero; 7004 = wrote pieces side by side; 740 = put the 4 in the wrong place. | S40: 1 | T40: auto-key | U40: system | V40: Missouri Learning Standards (DESE 2016); Common Core 2.NBT.A; base-ten manipulatives | W40: Ready | X40: 2026-05-22
...

Sheet Enums
A1: Item type | B1: Scoring method | C1: Who scores | D1: Form / Use | E1: Recipe type | F1: Status
A2: MC | B2: auto-key | C2: system | D2: Lesson practice | E2: Conceptual | F2: Draft
A3: Constructed | B3: rubric | C3: adult | D3: Lesson mastery | E3: Procedural | F3: Review
A4: Performance | B4: observed sign-off | C4: qualified evaluator | D4: Summative A | E4: Regulatory | F4: Ready
D5: Delayed B | E5: Strategic | F5: Retired
D6: Capstone | E6: Comparative
D7: Performance task | E7: Diagnostic
D8: Decode game | E8: System
E9: Analytical
E10: Interpersonal
E11: Reflective
E12: Historical

Sheet Coverage
A1: Standard code | B1: Total items | C1: MC | D1: Constructed | E1: Performance | F1: Summative A | G1: Delayed B | H1: Capstone
A2: 2.NBT.A.1 | B2: =COUNTIF(Items!$B:$B,$A2) -> 11 | C2: =COUNTIFS(Items!$B:$B,$A2,Items!$H:$H,"MC") -> 9 | D2: =COUNTIFS(Items!$B:$B,$A2,Items!$H:$H,"Constructed") -> 1 | E2: =COUNTIFS(Items!$B:$B,$A2,Items!$H:$H,"Performance") -> 1 | F2: =COUNTIFS(Items!$B:$B,$A2,Items!$J:$J,"Summative A") -> 1 | G2: =COUNTIFS(Items!$B:$B,$A2,Items!$J:$J,"Delayed B") -> 0 | H2: =COUNTIFS(Items!$B:$B,$A2,Items!$J:$J,"Capstone") -> 2
A3: 2.NBT.A.2 | B3: =COUNTIF(Items!$B:$B,$A3) -> 21 | C3: =COUNTIFS(Items!$B:$B,$A3,Items!$H:$H,"MC") -> 18 | D3: =COUNTIFS(Items!$B:$B,$A3,Items!$H:$H,"Constructed") -> 2 | E3: =COUNTIFS(Items!$B:$B,$A3,Items!$H:$H,"Performance") -> 1 | F3: =COUNTIFS(Items!$B:$B,$A3,Items!$J:$J,"Summative A") -> 9 | G3: =COUNTIFS(Items!$B:$B,$A3,Items!$J:$J,"Delayed B") -> 9 | H3: =COUNTIFS(Items!$B:$B,$A3,Items!$J:$J,"Capstone") -> 2
A4: 2.NBT.A.3 | B4: =COUNTIF(Items!$B:$B,$A4) -> 21 | C4: =COUNTIFS(Items!$B:$B,$A4,Items!$H:$H,"MC") -> 18 | D4: =COUNTIFS(Items!$B:$B,$A4,Items!$H:$H,"Constructed") -> 2 | E4: =COUNTIFS(Items!$B:$B,$A4,Items!$H:$H,"Performance") -> 1 | F4: =COUNTIFS(Items!$B:$B,$A4,Items!$J:$J,"Summative A") -> 9 | G4: =COUNTIFS(Items!$B:$B,$A4,Items!$J:$J,"Delayed B") -> 9 | H4: =COUNTIFS(Items!$B:$B,$A4,Items!$J:$J,"Capstone") -> 2
A5: 2.NBT.A.4 | B5: =COUNTIF(Items!$B:$B,$A5) -> 21 | C5: =COUNTIFS(Items!$B:$B,$A5,Items!$H:$H,"MC") -> 18 | D5: =COUNTIFS(Items!$B:$B,$A5,Items!$H:$H,"Constructed") -> 2 | E5: =COUNTIFS(Items!$B:$B,$A5,Items!$H:$H,"Performance") -> 1 | F5: =COUNTIFS(Items!$B:$B,$A5,Items!$J:$J,"Summative A") -> 9 | G5: =COUNTIFS(Items!$B:$B,$A5,Items!$J:$J,"Delayed B") -> 9 | H5: =COUNTIFS(Items!$B:$B,$A5,Items!$J:$J,"Capstone") -> 2
A6: 2.NBT.A.5 | B6: =COUNTIF(Items!$B:$B,$A6) -> 21 | C6: =COUNTIFS(Items!$B:$B,$A6,Items!$H:$H,"MC") -> 18 | D6: =COUNTIFS(Items!$B:$B,$A6,Items!$H:$H,"Constructed") -> 2 | E6: =COUNTIFS(Items!$B:$B,$A6,Items!$H:$H,"Performance") -> 1 | F6: =COUNTIFS(Items!$B:$B,$A6,Items!$J:$J,"Summative A") -> 9 | G6: =COUNTIFS(Items!$B:$B,$A6,Items!$J:$J,"Delayed B") -> 9 | H6: =COUNTIFS(Items!$B:$B,$A6,Items!$J:$J,"Capstone") -> 2
A7: TOTAL | B7: =SUM(B2:B6) -> 95 | C7: =SUM(C2:C6) -> 81 | D7: =SUM(D2:D6) -> 9 | E7: =SUM(E2:E6) -> 5 | F7: =SUM(F2:F6) -> 37 | G7: =SUM(G2:G6) -> 36 | H7: =SUM(H2:H6) -> 10
